2022-01-20 09:30:43,412 INFO    MainThread:9744 [wandb_setup.py:_flush():71] setting env: {}
2022-01-20 09:30:43,412 INFO    MainThread:9744 [wandb_setup.py:_flush():71] setting login settings: {}
2022-01-20 09:30:43,413 INFO    MainThread:9744 [wandb_init.py:_log_setup():371] Logging user logs to C:\Users\mailt\OneDrive\Dokumenter\GitHub\mlops_fuzzy-fish-waffle\outputs\2022-01-20\09-30-38\wandb\run-20220120_093043-1a4ctlzd\logs\debug.log
2022-01-20 09:30:43,413 INFO    MainThread:9744 [wandb_init.py:_log_setup():372] Logging internal logs to C:\Users\mailt\OneDrive\Dokumenter\GitHub\mlops_fuzzy-fish-waffle\outputs\2022-01-20\09-30-38\wandb\run-20220120_093043-1a4ctlzd\logs\debug-internal.log
2022-01-20 09:30:43,413 INFO    MainThread:9744 [wandb_init.py:init():404] calling init triggers
2022-01-20 09:30:43,414 INFO    MainThread:9744 [wandb_init.py:init():411] wandb.init called with sweep_config: {}
config: {}
2022-01-20 09:30:43,414 INFO    MainThread:9744 [wandb_init.py:init():460] starting backend
2022-01-20 09:30:43,414 INFO    MainThread:9744 [backend.py:_multiprocessing_setup():101] multiprocessing start_methods=spawn, using: spawn
2022-01-20 09:30:43,418 INFO    MainThread:9744 [backend.py:ensure_launched():216] starting backend process...
2022-01-20 09:30:43,431 ERROR   MainThread:9744 [wandb_init.py:init():958] error
Traceback (most recent call last):
  File "C:\Users\mailt\anaconda3\envs\mlops\lib\site-packages\wandb\sdk\wandb_init.py", line 931, in init
    run = wi.init()
  File "C:\Users\mailt\anaconda3\envs\mlops\lib\site-packages\wandb\sdk\wandb_init.py", line 467, in init
    backend.ensure_launched()
  File "C:\Users\mailt\anaconda3\envs\mlops\lib\site-packages\wandb\sdk\backend\backend.py", line 219, in ensure_launched
    self.wandb_process.start()
  File "C:\Users\mailt\anaconda3\envs\mlops\lib\multiprocessing\process.py", line 112, in start
    self._popen = self._Popen(self)
  File "C:\Users\mailt\anaconda3\envs\mlops\lib\multiprocessing\context.py", line 322, in _Popen
    return Popen(process_obj)
  File "C:\Users\mailt\anaconda3\envs\mlops\lib\multiprocessing\popen_spawn_win32.py", line 46, in __init__
    prep_data = spawn.get_preparation_data(process_obj._name)
  File "C:\Users\mailt\anaconda3\envs\mlops\lib\multiprocessing\spawn.py", line 143, in get_preparation_data
    _check_not_importing_main()
  File "C:\Users\mailt\anaconda3\envs\mlops\lib\multiprocessing\spawn.py", line 136, in _check_not_importing_main
    is not going to be frozen to produce an executable.''')
RuntimeError: 
        An attempt has been made to start a new process before the
        current process has finished its bootstrapping phase.

        This probably means that you are not using fork to start your
        child processes and you have forgotten to use the proper idiom
        in the main module:

            if __name__ == '__main__':
                freeze_support()
                ...

        The "freeze_support()" line can be omitted if the program
        is not going to be frozen to produce an executable.
