2022-01-19 12:17:06,017 INFO    MainThread:15168 [wandb_setup.py:_flush():71] setting env: {}
2022-01-19 12:17:06,017 INFO    MainThread:15168 [wandb_setup.py:_flush():71] setting login settings: {}
2022-01-19 12:17:06,018 INFO    MainThread:15168 [wandb_init.py:_log_setup():371] Logging user logs to C:\Users\bgran\OneDrive - Danmarks Tekniske Universitet\studies\Machine Learning Operations\mlops_fuzzy-fish-waffle\outputs\2022-01-19\12-17-02\wandb\run-20220119_121706-31u6ufd0\logs\debug.log
2022-01-19 12:17:06,018 INFO    MainThread:15168 [wandb_init.py:_log_setup():372] Logging internal logs to C:\Users\bgran\OneDrive - Danmarks Tekniske Universitet\studies\Machine Learning Operations\mlops_fuzzy-fish-waffle\outputs\2022-01-19\12-17-02\wandb\run-20220119_121706-31u6ufd0\logs\debug-internal.log
2022-01-19 12:17:06,019 INFO    MainThread:15168 [wandb_init.py:init():404] calling init triggers
2022-01-19 12:17:06,019 INFO    MainThread:15168 [wandb_init.py:init():409] wandb.init called with sweep_config: {}
config: {}
2022-01-19 12:17:06,019 INFO    MainThread:15168 [wandb_init.py:init():460] starting backend
2022-01-19 12:17:06,020 INFO    MainThread:15168 [backend.py:_multiprocessing_setup():99] multiprocessing start_methods=spawn, using: spawn
2022-01-19 12:17:06,025 INFO    MainThread:15168 [backend.py:ensure_launched():216] starting backend process...
2022-01-19 12:17:06,084 ERROR   MainThread:15168 [wandb_init.py:init():958] error
Traceback (most recent call last):
  File "C:\Users\bgran\anaconda3\envs\my_environment\lib\site-packages\wandb\sdk\wandb_init.py", line 931, in init
    run = wi.init()
  File "C:\Users\bgran\anaconda3\envs\my_environment\lib\site-packages\wandb\sdk\wandb_init.py", line 467, in init
    backend.ensure_launched()
  File "C:\Users\bgran\anaconda3\envs\my_environment\lib\site-packages\wandb\sdk\backend\backend.py", line 219, in ensure_launched
    self.wandb_process.start()
  File "C:\Users\bgran\anaconda3\envs\my_environment\lib\multiprocessing\process.py", line 121, in start
    self._popen = self._Popen(self)
  File "C:\Users\bgran\anaconda3\envs\my_environment\lib\multiprocessing\context.py", line 327, in _Popen
    return Popen(process_obj)
  File "C:\Users\bgran\anaconda3\envs\my_environment\lib\multiprocessing\popen_spawn_win32.py", line 45, in __init__
    prep_data = spawn.get_preparation_data(process_obj._name)
  File "C:\Users\bgran\anaconda3\envs\my_environment\lib\multiprocessing\spawn.py", line 154, in get_preparation_data
    _check_not_importing_main()
  File "C:\Users\bgran\anaconda3\envs\my_environment\lib\multiprocessing\spawn.py", line 134, in _check_not_importing_main
    raise RuntimeError('''
RuntimeError: 
        An attempt has been made to start a new process before the
        current process has finished its bootstrapping phase.

        This probably means that you are not using fork to start your
        child processes and you have forgotten to use the proper idiom
        in the main module:

            if __name__ == '__main__':
                freeze_support()
                ...

        The "freeze_support()" line can be omitted if the program
        is not going to be frozen to produce an executable.
