2022-01-20 09:22:22,762 INFO    MainThread:29360 [internal.py:wandb_internal():87] W&B internal server running at pid: 29360, started at: 2022-01-20 09:22:22.761024
2022-01-20 09:22:22,772 INFO    WriterThread:29360 [datastore.py:open_for_write():77] open: C:\Users\Durita Kvilt\OneDrive\Menneske orienteret kunstig intelligens\Machine learning operations\mlops_fuzzy-fish-waffle\wandb\run-20220120_092219-17nmc2vy\run-17nmc2vy.wandb
2022-01-20 09:22:22,772 DEBUG   HandlerThread:29360 [handler.py:handle_request():130] handle_request: check_version
2022-01-20 09:22:22,773 DEBUG   SenderThread:29360 [sender.py:send():234] send: header
2022-01-20 09:22:22,773 DEBUG   SenderThread:29360 [sender.py:send_request():248] send_request: check_version
2022-01-20 09:22:22,930 DEBUG   SenderThread:29360 [sender.py:send():234] send: run
2022-01-20 09:22:23,180 ERROR   SenderThread:29360 [internal_api.py:execute():144] 404 response executing GraphQL.
2022-01-20 09:22:23,180 ERROR   SenderThread:29360 [internal_api.py:execute():145] {"errors":[{"message":"project not found","path":["upsertBucket"]}],"data":{"upsertBucket":null}}
2022-01-20 09:22:23,930 INFO    WriterThread:29360 [datastore.py:close():281] close: C:\Users\Durita Kvilt\OneDrive\Menneske orienteret kunstig intelligens\Machine learning operations\mlops_fuzzy-fish-waffle\wandb\run-20220120_092219-17nmc2vy\run-17nmc2vy.wandb
2022-01-20 09:22:23,930 INFO    HandlerThread:29360 [handler.py:finish():731] shutting down handler
2022-01-20 09:22:23,930 ERROR   MainThread:29360 [internal.py:wandb_internal():158] Thread SenderThread:
Traceback (most recent call last):
  File "C:\Users\Durita Kvilt\AppData\Local\Programs\Python\Python39\lib\site-packages\wandb\sdk\lib\retry.py", line 102, in __call__
    result = self._call_fn(*args, **kwargs)
  File "C:\Users\Durita Kvilt\AppData\Local\Programs\Python\Python39\lib\site-packages\wandb\sdk\internal\internal_api.py", line 147, in execute
    six.reraise(*sys.exc_info())
  File "C:\Users\Durita Kvilt\AppData\Local\Programs\Python\Python39\lib\site-packages\six.py", line 703, in reraise
    raise value
  File "C:\Users\Durita Kvilt\AppData\Local\Programs\Python\Python39\lib\site-packages\wandb\sdk\internal\internal_api.py", line 141, in execute
    return self.client.execute(*args, **kwargs)
  File "C:\Users\Durita Kvilt\AppData\Local\Programs\Python\Python39\lib\site-packages\wandb\vendor\gql-0.2.0\gql\client.py", line 52, in execute
    result = self._get_result(document, *args, **kwargs)
  File "C:\Users\Durita Kvilt\AppData\Local\Programs\Python\Python39\lib\site-packages\wandb\vendor\gql-0.2.0\gql\client.py", line 60, in _get_result
    return self.transport.execute(document, *args, **kwargs)
  File "C:\Users\Durita Kvilt\AppData\Local\Programs\Python\Python39\lib\site-packages\wandb\vendor\gql-0.2.0\gql\transport\requests.py", line 39, in execute
    request.raise_for_status()
  File "C:\Users\Durita Kvilt\AppData\Local\Programs\Python\Python39\lib\site-packages\requests\models.py", line 953, in raise_for_status
    raise HTTPError(http_error_msg, response=self)
requests.exceptions.HTTPError: 404 Client Error: Not Found for url: https://api.wandb.ai/graphql

During handling of the above exception, another exception occurred:

Traceback (most recent call last):
  File "C:\Users\Durita Kvilt\AppData\Local\Programs\Python\Python39\lib\site-packages\wandb\apis\normalize.py", line 24, in wrapper
    return func(*args, **kwargs)
  File "C:\Users\Durita Kvilt\AppData\Local\Programs\Python\Python39\lib\site-packages\wandb\sdk\internal\internal_api.py", line 1298, in upsert_run
    response = self.gql(mutation, variable_values=variable_values, **kwargs)
  File "C:\Users\Durita Kvilt\AppData\Local\Programs\Python\Python39\lib\site-packages\wandb\sdk\lib\retry.py", line 118, in __call__
    if not check_retry_fn(e):
  File "C:\Users\Durita Kvilt\AppData\Local\Programs\Python\Python39\lib\site-packages\wandb\util.py", line 821, in no_retry_auth
    raise CommError("Permission denied, ask the project owner to grant you access")
wandb.errors.CommError: Permission denied, ask the project owner to grant you access

During handling of the above exception, another exception occurred:

Traceback (most recent call last):
  File "C:\Users\Durita Kvilt\AppData\Local\Programs\Python\Python39\lib\site-packages\wandb\sdk\internal\internal_util.py", line 52, in run
    self._run()
  File "C:\Users\Durita Kvilt\AppData\Local\Programs\Python\Python39\lib\site-packages\wandb\sdk\internal\internal_util.py", line 102, in _run
    self._process(record)
  File "C:\Users\Durita Kvilt\AppData\Local\Programs\Python\Python39\lib\site-packages\wandb\sdk\internal\internal.py", line 291, in _process
    self._sm.send(record)
  File "C:\Users\Durita Kvilt\AppData\Local\Programs\Python\Python39\lib\site-packages\wandb\sdk\internal\sender.py", line 236, in send
    send_handler(record)
  File "C:\Users\Durita Kvilt\AppData\Local\Programs\Python\Python39\lib\site-packages\wandb\sdk\internal\sender.py", line 687, in send_run
    self._init_run(run, config_value_dict)
  File "C:\Users\Durita Kvilt\AppData\Local\Programs\Python\Python39\lib\site-packages\wandb\sdk\internal\sender.py", line 711, in _init_run
    server_run, inserted = self._api.upsert_run(
  File "C:\Users\Durita Kvilt\AppData\Local\Programs\Python\Python39\lib\site-packages\wandb\apis\normalize.py", line 62, in wrapper
    six.reraise(CommError, CommError(message, err), sys.exc_info()[2])
  File "C:\Users\Durita Kvilt\AppData\Local\Programs\Python\Python39\lib\site-packages\six.py", line 702, in reraise
    raise value.with_traceback(tb)
  File "C:\Users\Durita Kvilt\AppData\Local\Programs\Python\Python39\lib\site-packages\wandb\apis\normalize.py", line 24, in wrapper
    return func(*args, **kwargs)
  File "C:\Users\Durita Kvilt\AppData\Local\Programs\Python\Python39\lib\site-packages\wandb\sdk\internal\internal_api.py", line 1298, in upsert_run
    response = self.gql(mutation, variable_values=variable_values, **kwargs)
  File "C:\Users\Durita Kvilt\AppData\Local\Programs\Python\Python39\lib\site-packages\wandb\sdk\lib\retry.py", line 118, in __call__
    if not check_retry_fn(e):
  File "C:\Users\Durita Kvilt\AppData\Local\Programs\Python\Python39\lib\site-packages\wandb\util.py", line 821, in no_retry_auth
    raise CommError("Permission denied, ask the project owner to grant you access")
wandb.errors.CommError: Permission denied, ask the project owner to grant you access
2022-01-20 09:22:26,173 INFO    MainThread:29360 [internal.py:handle_exit():77] Internal process exited
